<?xml version="1.0" encoding="UTF-8"?>
<!-- Generated by org.testng.reporters.JUnitReportReporter -->
<testsuite hostname="DESKTOP-0BMU726" failures="1" tests="6" name="test_cases.verifyMultilpeCredentials_Test" time="86.822" errors="0" timestamp="2023-12-21T16:20:59 IST" skipped="0">
  <testcase classname="test_cases.verifyMultilpeCredentials_Test" name="loginToMultipleCredentials" time="5.212">
    <failure message="The following asserts failed:
	expected [https://www.saucedemo.com/] but found [https://www.saucedemo.com/inventory.html]" type="java.lang.AssertionError">
      <![CDATA[java.lang.AssertionError: The following asserts failed:
expected [https://www.saucedemo.com/] but found [https://www.saucedemo.com/inventory.html]
at org.testng.asserts.SoftAssert.assertAll(SoftAssert.java:46)
at org.testng.asserts.SoftAssert.assertAll(SoftAssert.java:30)
at test_cases.verifyMultilpeCredentials_Test.loginToMultipleCredentials(verifyMultilpeCredentials_Test.java:50)
at java.base/jdk.internal.reflect.NativeMethodAccessorImpl.invoke0(Native Method)
at java.base/jdk.internal.reflect.NativeMethodAccessorImpl.invoke(NativeMethodAccessorImpl.java:77)
at java.base/jdk.internal.reflect.DelegatingMethodAccessorImpl.invoke(DelegatingMethodAccessorImpl.java:43)
at java.base/java.lang.reflect.Method.invoke(Method.java:568)
at org.testng.internal.invokers.MethodInvocationHelper.invokeMethod(MethodInvocationHelper.java:139)
at org.testng.internal.invokers.TestInvoker.invokeMethod(TestInvoker.java:677)
at org.testng.internal.invokers.TestInvoker.invokeTestMethod(TestInvoker.java:221)
at org.testng.internal.invokers.MethodRunner.runInSequence(MethodRunner.java:50)
at org.testng.internal.invokers.TestInvoker$MethodInvocationAgent.invoke(TestInvoker.java:969)
at org.testng.internal.invokers.TestInvoker.invokeTestMethods(TestInvoker.java:194)
at org.testng.internal.invokers.TestMethodWorker.invokeTestMethods(TestMethodWorker.java:148)
at org.testng.internal.invokers.TestMethodWorker.run(TestMethodWorker.java:128)
at java.base/java.util.ArrayList.forEach(ArrayList.java:1511)
at org.testng.TestRunner.privateRun(TestRunner.java:829)
at org.testng.TestRunner.run(TestRunner.java:602)
at org.testng.SuiteRunner.runTest(SuiteRunner.java:437)
at org.testng.SuiteRunner.runSequentially(SuiteRunner.java:431)
at org.testng.SuiteRunner.privateRun(SuiteRunner.java:391)
at org.testng.SuiteRunner.run(SuiteRunner.java:330)
at org.testng.SuiteRunnerWorker.runSuite(SuiteRunnerWorker.java:52)
at org.testng.SuiteRunnerWorker.run(SuiteRunnerWorker.java:95)
at org.testng.TestNG.runSuitesSequentially(TestNG.java:1256)
at org.testng.TestNG.runSuitesLocally(TestNG.java:1176)
at org.testng.TestNG.runSuites(TestNG.java:1099)
at org.testng.TestNG.run(TestNG.java:1067)
at org.testng.remote.AbstractRemoteTestNG.run(AbstractRemoteTestNG.java:115)
at org.testng.remote.RemoteTestNG.initAndRun(RemoteTestNG.java:251)
at org.testng.remote.RemoteTestNG.main(RemoteTestNG.java:77)
]]>
    </failure>
  </testcase> <!-- loginToMultipleCredentials -->
  <system-out/>
  <testcase classname="test_cases.verifyMultilpeCredentials_Test" name="loginToMultipleCredentials" time="5.469"/>
  <system-out/>
  <testcase classname="test_cases.verifyMultilpeCredentials_Test" name="loginToMultipleCredentials" time="5.393"/>
  <system-out/>
  <testcase classname="test_cases.verifyMultilpeCredentials_Test" name="loginToMultipleCredentials" time="54.134"/>
  <system-out/>
  <testcase classname="test_cases.verifyMultilpeCredentials_Test" name="loginToMultipleCredentials" time="11.076"/>
  <system-out/>
  <testcase classname="test_cases.verifyMultilpeCredentials_Test" name="loginToMultipleCredentials" time="5.538"/>
  <system-out/>
</testsuite> <!-- test_cases.verifyMultilpeCredentials_Test -->
